Workbook

Sheet Attendance 10 FEMALES
A1: SN | B1: Name (English) | C1: Name (Arabic) | D1: Academic ID | E1: 45931 | F1: 45936 | G1: 45937 | H1: 45938 | I1: 45943 | J1: 45945 | K1: 45950 | L1: 45952 | M1: 45957 | N1: 45959 | O1: 45964 | P1: 45966 | Q1: 45971 | R1: 45973 | S1: 45992 | T1: 45994 | U1: 45999 | V1: 46001 | W1: 46006 | X1: 46008 | Y1: 46013 | Z1: 46015 | AA1: 46020 | AB1: 46021 | AC1: Total Absent | AD1: Total Attendence | AE1: Total Points
A2: 1 | B2: Maryam Nasser Khalid Yousef | C2: مريم ناصر خالد يوسف | D2: 331072239 | E2: Present | F2: Present | G2: Present | H2: Present | I2: Present | J2: Present | K2: Present | L2: Present | M2: Present | N2: Present | O2: Present | P2: Absent | Q2: Present | R2: Present | S2: Present | T2: Present | U2: Absent | V2: Present | W2: Present | X2: Present | Y2: Present | Z2: Present | AA2: Present | AB2: Present | AC2: =COUNTIF(E2:AB2,"Absent") | AD2: =COUNTIF(E2:AB2,"Present") | AE2: =(AD2*5)+(AC2*-5)
A3: 2 | B3: Amal Fahad Majed Marwan | C3: أمل فهد ماجد مروان | D3: 368255186 | E3: Present | F3: Present | G3: Present | H3: Present | I3: Present | J3: Present | K3: Present | L3: Absent | M3: Present | N3: Present | O3: Present | P3: Present | Q3: Present | R3: Absent | S3: Present | T3: Present | U3: Absent | V3: Present | W3: Present | X3: Absent | Y3: Absent | Z3: Present | AA3: Absent | AB3: Absent | AC3: =COUNTIF(E3:AB3,"Absent") | AD3: =COUNTIF(E3:AB3,"Present") | AE3: =(AD3*5)+(AC3*-5)
A4: 3 | B4: Aljoharah Hussam Sultan Waleed | C4: الجوهرة حسام سلطان وليد | D4: 405438133 | E4: Present | F4: Present | G4: Absent | H4: Present | I4: Present | J4: Present | K4: Present | L4: Present | M4: Absent | N4: Present | O4: Present | P4: Present | Q4: Present | R4: Present | S4: Present | T4: Present | U4: Absent | V4: Present | W4: Present | X4: Absent | Y4: Present | Z4: Present | AA4: Present | AB4: Present | AC4: =COUNTIF(E4:AB4,"Absent") | AD4: =COUNTIF(E4:AB4,"Present") | AE4: =(AD4*5)+(AC4*-5)
A5: 4 | B5: Leen Ahmed Hussein Nawaf | C5: لين أحمد حسين نواف | D5: 442621080 | E5: Present | F5: Present | G5: Present | H5: Present | I5: Present | J5: Absent | K5: Present | L5: Present | M5: Present | N5: Present | O5: Present | P5: Present | Q5: Present | R5: Present | S5: Present | T5: Present | U5: Present | V5: Present | W5: Present | X5: Absent | Y5: Present | Z5: Present | AA5: Present | AB5: Present | AC5: =COUNTIF(E5:AB5,"Absent") | AD5: =COUNTIF(E5:AB5,"Present") | AE5: =(AD5*5)+(AC5*-5)
A6: 5 | B6: Ghina Omar Rayan Yazeed | C6: غنى عمر ريان يزيد | D6: 479804027 | E6: Present | F6: Present | G6: Present | H6: Present | I6: Absent | J6: Present | K6: Present | L6: Present | M6: Present | N6: Present | O6: Present | P6: Present | Q6: Absent | R6: Present | S6: Present | T6: Present | U6: Present | V6: Present | W6: Absent | X6: Absent | Y6: Absent | Z6: Absent | AA6: Present | AB6: Absent | AC6: =COUNTIF(E6:AB6,"Absent") | AD6: =COUNTIF(E6:AB6,"Present") | AE6: =(AD6*5)+(AC6*-5)
A7: 6 | B7: Hatoon Saif Mansour Ibrahim | C7: هتون سيف منصور إبراهيم | D7: 516986974 | E7: Present | F7: Absent | G7: Absent | H7: Present | I7: Present | J7: Present | K7: Present | L7: Present | M7: Present | N7: Absent | O7: Present | P7: Present | Q7: Absent | R7: Present | S7: Present | T7: Present | U7: Present | V7: Absent | W7: Present | X7: Present | Y7: Present | Z7: Present | AA7: Absent | AB7: Present | AC7: =COUNTIF(E7:AB7,"Absent") | AD7: =COUNTIF(E7:AB7,"Present") | AE7: =(AD7*5)+(AC7*-5)
A8: 7 | B8: Wafa Abdullah Iyad Bassam | C8: وفاء عبدالله إياد بسام | D8: 554169921 | E8: Present | F8: Present | G8: Present | H8: Present | I8: Present | J8: Present | K8: Present | L8: Present | M8: Present | N8: Present | O8: Absent | P8: Absent | Q8: Present | R8: Present | S8: Absent | T8: Present | U8: Present | V8: Present | W8: Absent | X8: Present | Y8: Present | Z8: Present | AA8: Absent | AB8: Absent | AC8: =COUNTIF(E8:AB8,"Absent") | AD8: =COUNTIF(E8:AB8,"Present") | AE8: =(AD8*5)+(AC8*-5)
A9: 8 | B9: Amani Saad Nayef Hamad | C9: أماني سعد نايف حمد | D9: 591352868 | E9: Present | F9: Present | G9: Present | H9: Present | I9: Present | J9: Present | K9: Present | L9: Present | M9: Present | N9: Present | O9: Present | P9: Present | Q9: Present | R9: Present | S9: Present | T9: Present | U9: Absent | V9: Present | W9: Present | X9: Present | Y9: Present | Z9: Absent | AA9: Excused absence | AB9: Present | AC9: =COUNTIF(E9:AB9,"Absent") | AD9: =COUNTIF(E9:AB9,"Present") | AE9: =(AD9*5)+(AC9*-5)
A10: 9 | B10: Moudi Hamed Hamad Tamim | C10: موضي حامد حمد تميم | D10: 628535815 | E10: Present | F10: Present | G10: Absent | H10: Present | I10: Present | J10: Excused absence | K10: Present | L10: Present | M10: Present | N10: Present | O10: Absent | P10: Absent | Q10: Present | R10: Present | S10: Absent | T10: Present | U10: Present | V10: Present | W10: Present | X10: Present | Y10: Absent | Z10: Present | AA10: Absent | AB10: Present | AC10: =COUNTIF(E10:AB10,"Absent") | AD10: =COUNTIF(E10:AB10,"Present") | AE10: =(AD10*5)+(AC10*-5)
A11: 10 | B11: Layan Ziyad Adnan Omar | C11: ليان زياد عدنان عمر | D11: 665718762 | E11: Present | F11: Present | G11: Present | H11: Present | I11: Present | J11: Present | K11: Present | L11: Present | M11: Present | N11: Present | O11: Present | P11: Present | Q11: Present | R11: Present | S11: Absent | T11: Present | U11: Present | V11: Absent | W11: Absent | X11: Absent | Y11: Absent | Z11: Present | AA11: Present | AB11: Present | AC11: =COUNTIF(E11:AB11,"Absent") | AD11: =COUNTIF(E11:AB11,"Present") | AE11: =(AD11*5)+(AC11*-5)
A12: 11 | B12: Rawan Rayan Rakan Fawaz | C12: روان ريان راكان فواز | D12: 702901709 | E12: Present | F12: Present | G12: Present | H12: Present | I12: Present | J12: Present | K12: Present | L12: Present | M12: Present | N12: Present | O12: Present | P12: Present | Q12: Present | R12: Present | S12: Present | T12: Present | U12: Absent | V12: Present | W12: Present | X12: Excused absence | Y12: Present | Z12: Present | AA12: Present | AB12: Absent | AC12: =COUNTIF(E12:AB12,"Absent") | AD12: =COUNTIF(E12:AB12,"Present") | AE12: =(AD12*5)+(AC12*-5)
A13: 12 | B13: Sarah Faisal Mohannad Yousef | C13: سارة فيصل مهند يوسف | D13: 740084656 | E13: Present | F13: Present | G13: Present | H13: Present | I13: Present | J13: Absent | K13: Present | L13: Absent | M13: Present | N13: Present | O13: Absent | P13: Absent | Q13: Present | R13: Present | S13: Present | T13: Present | U13: Present | V13: Absent | W13: Present | X13: Present | Y13: Present | Z13: Present | AA13: Present | AB13: Excused absence | AC13: =COUNTIF(E13:AB13,"Absent") | AD13: =COUNTIF(E13:AB13,"Present") | AE13: =(AD13*5)+(AC13*-5)
... A38: 37 | B38: Maryam Mansour Ayman Tariq | C38: مريم منصور أيمن طارق | D38: 669658331 | E38: Present | F38: Excused absence | G38: Present | H38: Present | I38: Present | J38: Present | K38: Absent | L38: Present | M38: Present | N38: Present | O38: Present | P38: Present | Q38: Present | R38: Present | S38: Absent | T38: Present | U38: Absent | V38: Present | W38: Absent | X38: Excused absence | Y38: Present | Z38: Absent | AA38: Present | AB38: Excused absence | AC38: =COUNTIF(E38:AB38,"Absent") | AD38: =COUNTIF(E38:AB38,"Present") | AE38: =(AD38*5)+(AC38*-5)
A39: 38 | B39: Lana Rashid Abdulaziz Muath | C39: لانا راشد عبدالعزيز معاذ | D39: 706841278 | E39: Present | F39: Absent | G39: Excused absence | H39: Present | I39: Absent | J39: Present | K39: Absent | L39: Absent | M39: Present | N39: Present | O39: Absent | P39: Absent | Q39: Present | R39: Absent | S39: إضافة جديدة من 8 ديسمبر | U39: Absent | V39: Absent | W39: Absent | X39: Absent | Y39: Absent | Z39: Absent | AA39: Present | AB39: Present | AC39: =COUNTIF(E39:AB39,"Absent") | AD39: =COUNTIF(E39:AB39,"Present") | AE39: =(AD39*5)+(AC39*-5)
A40: 39 | E40: Present | F40: Present | G40: Present | H40: Present | I40: Present | J40: Present | K40: Absent | L40: Present | M40: Present | N40: Excused absence | O40: Absent | P40: Present | Q40: Present | R40: Present | S40: Present | T40: Absent | U40: Absent | V40: Present | W40: Absent | X40: Present | Y40: Absent | Z40: Absent | AA40: Present | AB40: Absent | AC40: =COUNTIF(E40:AB40,"Absent") | AD40: =COUNTIF(E40:AB40,"Present") | AE40: =(AD40*5)+(AC40*-5)
E41: Absent | F41: Present | G41: Present | H41: Present | I41: Present | J41: Present | K41: Present | L41: Excused absence | M41: Absent | N41: Present | O41: Absent | P41: Present | Q41: Present | R41: Present | S41: Present | T41: Absent | U41: Present | V41: Present | W41: Absent | X41: Present | Y41: Absent | Z41: Present | AA41: Excused absence | AB41: Absent | AC41: Present | AD41: Present | AE41: Present
E42: Absent | F42: Present | G42: Excused absence | H42: Absent | I42: Present | J42: Present | K42: Absent | L42: Present | M42: Present | N42: Present | O42: Present | P42: Present | Q42: Present | R42: Absent | S42: Present | T42: Absent | U42: Present | V42: Present | W42: Present | X42: Present | Y42: Present | Z42: Present | AA42: Absent | AB42: Absent | AC42: Present | AD42: Present | AE42: Present
E43: Present | F43: Present | G43: Absent | H43: Present | I43: Present | J43: Present | K43: Present | L43: Present | M43: Absent | N43: Absent | O43: Present | P43: Present | Q43: Present | R43: Present | S43: Present | T43: Absent | U43: Absent | V43: Present | W43: Excused absence | X43: Present | Y43: Present | Z43: Present | AA43: Excused absence | AB43: Absent | AC43: Present | AD43: Excused absence | AE43: Present
E44: Absent | F44: Present | G44: Present | H44: Present | I44: Present | J44: Present | K44: Present | L44: Present | M44: Absent | N44: Present | O44: Present | P44: Present | Q44: Present | R44: Present | S44: Present | T44: Present | U44: Present | V44: Absent | W44: Present | X44: Absent | Y44: Absent | Z44: Present | AA44: Present | AB44: Absent | AC44: Absent | AD44: Absent | AE44: Present
A45: There is no data | C45: First Online Session (Special Case) | E45: Absent | F45: Present | G45: Absent | H45: Absent | I45: Absent | J45: Excused absence | K45: Absent | L45: Excused absence | M45: Absent | N45: Absent | O45: Absent | P45: Absent | Q45: Absent | R45: Absent | S45: Present | T45: Present | U45: Present | V45: Present | W45: Excused absence | X45: Present | Y45: Absent | Z45: Present | AA45: Excused absence | AB45: Absent | AC45: Excused absence | AD45: Present | AE45: Present
A46: The point where I stopped | E46: Present | F46: Present | G46: Present | H46: Present | I46: Present | J46: Present | K46: Present | L46: Absent | M46: Present | N46: Present | O46: Present | P46: Present | Q46: Present | R46: Present | S46: Present | T46: Present | U46: Present | V46: Absent | W46: Absent | X46: Present | Y46: Present | Z46: Present | AA46: Present | AB46: Present | AC46: Present | AD46: Absent | AE46: Present

Sheet Attendance 11 FEMALES
A1: SN | B1: Name (English) | C1: Name (Arabic) | D1: Academic ID | E1: 45931 | F1: 45936 | G1: 45937 | H1: 45938 | I1: 45943 | J1: 45945 | K1: 45950 | L1: 45952 | M1: 45957 | N1: 45959 | O1: 45964 | P1: 45966 | Q1: 45971 | R1: 45973 | S1: 45992 | T1: 45994 | U1: 45999 | V1: 46001 | W1: 46006 | X1: 46008 | Y1: 46013 | Z1: 46015 | AA1: 46020 | AB1: 46022 | AC1: Total Absent | AD1: Total Attendence | AE1: Total Points
A2: 1 | B2: Reema Rayan Nawaf Abdullah | C2: ريما ريان نواف عبدالله | D2: 333072239 | E2: Present | F2: Absent | G2: Present | H2: Present | I2: Present | J2: Excused absence | K2: Present | L2: Absent | M2: Present | N2: Present | O2: Absent | P2: Present | Q2: Present | R2: Absent | S2: Absent | T2: Present | U2: Absent | V2: Absent | W2: Absent | X2: Present | Y2: Present | Z2: Absent | AA2: Excused absence | AB2: Excused absence | AC2: =COUNTIF(E2:AB2,"Absent") | AD2: =COUNTIF(E2:AB2,"Present") | AE2: =(AD2*5)+(AC2*-5)
A3: 2 | B3: Reema Jaber Abdullah Mazen | C3: ريما جابر عبدالله مازن | D3: 370255186 | E3: Excused absence | F3: Present | G3: Present | H3: Present | I3: Present | J3: Present | K3: Present | L3: Present | M3: Present | N3: Present | O3: Present | P3: Present | Q3: Present | R3: Present | S3: Present | T3: Present | U3: Present | V3: Absent | W3: Absent | X3: Present | Y3: Present | Z3: Present | AA3: Absent | AB3: Present | AC3: =COUNTIF(E3:AB3,"Absent") | AD3: =COUNTIF(E3:AB3,"Present") | AE3: =(AD3*5)+(AC3*-5)
A4: 3 | B4: Ghada Nayef Yazeed Marwan | C4: غادة نايف يزيد مروان | D4: 407438133 | E4: Present | F4: Present | G4: Present | H4: Excused absence | I4: Present | J4: Present | K4: Absent | L4: Present | M4: Present | N4: Absent | O4: Absent | P4: Present | Q4: Present | R4: Absent | S4: Absent | T4: Absent | U4: Absent | V4: Present | W4: Absent | X4: Present | Y4: Present | Z4: Absent | AA4: Absent | AB4: Present | AC4: =COUNTIF(E4:AB4,"Absent") | AD4: =COUNTIF(E4:AB4,"Present") | AE4: =(AD4*5)+(AC4*-5)
A5: 4 | B5: Raghad Faisal Anas Yousef | C5: رغد فيصل أنس يوسف | D5: 444621080 | E5: Absent | F5: Present | G5: Present | H5: Present | I5: Present | J5: Present | K5: Absent | L5: Absent | M5: Present | N5: Present | O5: Present | P5: Absent | Q5: Present | R5: Absent | S5: Absent | T5: Present | U5: Present | V5: Absent | W5: Present | X5: Present | Y5: Present | Z5: Present | AA5: Present | AB5: Absent | AC5: =COUNTIF(E5:AB5,"Absent") | AD5: =COUNTIF(E5:AB5,"Present") | AE5: =(AD5*5)+(AC5*-5)
A6: 5 | B6: Atheer Hussam Majed Ali | C6: أثير حسام ماجد علي | D6: 481804027 | E6: Absent | F6: Absent | G6: Absent | H6: Present | I6: Present | J6: Present | K6: Present | L6: Present | M6: Absent | N6: Present | O6: Present | P6: Present | Q6: Present | R6: Present | S6: Absent | T6: Present | U6: Absent | V6: Present | W6: Absent | X6: Present | Y6: Present | Z6: Absent | AA6: Present | AB6: Present | AC6: =COUNTIF(E6:AB6,"Absent") | AD6: =COUNTIF(E6:AB6,"Present") | AE6: =(AD6*5)+(AC6*-5)
A7: 6 | B7: Wadha Hussein Mazen Abdulmalik | C7: وضحى حسين مازن عبدالملك | D7: 518986974 | E7: Present | F7: Present | G7: Present | H7: Present | I7: Excused absence | J7: Excused absence | K7: Absent | L7: Present | M7: Present | N7: Present | O7: Present | P7: Present | Q7: Present | R7: Present | S7: Present | T7: Present | U7: Present | V7: Absent | W7: Absent | X7: Absent | Y7: Present | Z7: Present | AA7: Present | AB7: Present | AC7: =COUNTIF(E7:AB7,"Absent") | AD7: =COUNTIF(E7:AB7,"Present") | AE7: =(AD7*5)+(AC7*-5)
A8: 7 | B8: Jana Abdullah Badr Ziyad | C8: جنى عبدالله بدر زياد | D8: 556169921 | E8: Absent | F8: Present | G8: Present | H8: Present | I8: Present | J8: Present | K8: Absent | L8: Present | M8: Present | N8: Present | O8: Present | P8: Present | Q8: Present | R8: Absent | S8: Present | T8: Present | U8: Present | V8: Present | W8: Absent | X8: Present | Y8: Present | Z8: Present | AA8: Present | AB8: Present | AC8: =COUNTIF(E8:AB8,"Absent") | AD8: =COUNTIF(E8:AB8,"Present") | AE8: =(AD8*5)+(AC8*-5)
A9: 8 | B9: Afnan Saleh Abdulrahman Badr | C9: أفنان صالح عبدالرحمن بدر | D9: 593352868 | E9: Excused absence | F9: Excused absence | G9: Present | H9: Excused absence | I9: Excused absence | J9: Excused absence | K9: Absent | L9: Absent | M9: Present | N9: Present | O9: Absent | P9: Present | Q9: Absent | R9: Present | S9: Absent | T9: Absent | U9: Absent | V9: Absent | W9: Absent | X9: Absent | Y9: Absent | Z9: Present | AA9: Present | AB9: Present | AC9: =COUNTIF(E9:AB9,"Absent") | AD9: =COUNTIF(E9:AB9,"Present") | AE9: =(AD9*5)+(AC9*-5)
A10: 9 | B10: Haneen Marwan Mansour Hadi | C10: حنين مروان منصور هادي | D10: 630535815 | E10: Present | F10: Present | G10: Absent | H10: Present | I10: Present | J10: Present | K10: Absent | L10: Present | M10: Present | N10: Absent | O10: Present | P10: Absent | Q10: Present | R10: Present | S10: Absent | T10: Present | U10: Absent | V10: Present | W10: Present | X10: Present | Y10: Absent | Z10: Present | AA10: Present | AB10: Present | AC10: =COUNTIF(E10:AB10,"Absent") | AD10: =COUNTIF(E10:AB10,"Present") | AE10: =(AD10*5)+(AC10*-5)
A11: 10 | B11: Fatimah Saleh Saud Ali | C11: فاطمة صالح سعود علي | D11: 667718762 | E11: Present | F11: Present | G11: Present | H11: Absent | I11: Present | J11: Present | K11: Absent | L11: Present | M11: Present | N11: Absent | O11: Present | P11: Present | Q11: Present | R11: Absent | S11: Absent | T11: Present | U11: Absent | V11: Present | W11: Absent | X11: Excused absence | Y11: Present | Z11: Present | AA11: Present | AB11: Absent | AC11: =COUNTIF(E11:AB11,"Absent") | AD11: =COUNTIF(E11:AB11,"Present") | AE11: =(AD11*5)+(AC11*-5)
A12: 11 | B12: Fatimah Basheer Nayef Faris | C12: فاطمة بشير نايف فارس | D12: 704901709 | E12: Absent | F12: Absent | G12: Present | H12: Absent | I12: Absent | J12: Absent | K12: Absent | L12: Absent | M12: Absent | N12: Absent | O12: Present | P12: Present | Q12: Absent | R12: Present | S12: Absent | T12: Absent | U12: Absent | V12: Absent | W12: Absent | X12: Excused absence | Y12: Present | Z12: Present | AA12: Absent | AB12: Absent | AC12: =COUNTIF(E12:AB12,"Absent") | AD12: =COUNTIF(E12:AB12,"Present") | AE12: =(AD12*5)+(AC12*-5)
A13: 12 | B13: Mashael Rami Marwan Basheer | C13: مشاعل رامي مروان بشير | D13: 742084656 | E13: Present | F13: Present | G13: Present | H13: Present | I13: Absent | J13: Present | K13: Absent | L13: Present | M13: Present | N13: Present | O13: Present | P13: Present | Q13: Present | R13: Present | S13: Present | T13: Present | U13: Absent | V13: Absent | W13: Present | X13: Absent | Y13: Absent | Z13: Absent | AA13: Present | AB13: Absent | AC13: =COUNTIF(E13:AB13,"Absent") | AD13: =COUNTIF(E13:AB13,"Present") | AE13: =(AD13*5)+(AC13*-5)
... A40: 39 | B40: Haya Saleh Rakan Rayan | C40: هيا صالح راكان ريان | D40: 746024225 | E40: Absent | F40: Absent | G40: Absent | H40: Absent | I40: Present | J40: Present | K40: Present | L40: Present | M40: Present | N40: Absent | O40: Absent | P40: Absent | Q40: Present | R40: Present | S40: Present | T40: Present | U40: Present | V40: Present | W40: Absent | X40: Excused absence | Y40: Present | Z40: Present | AA40: Present | AB40: Present | AC40: =COUNTIF(E40:AB40,"Absent") | AD40: =COUNTIF(E40:AB40,"Present") | AE40: =(AD40*5)+(AC40*-5)
B41: Isra Abdulaziz Mishari Ayman | C41: إسراء عبدالعزيز مشاري أيمن | D41: 783207172 | E41: إضافة جديدة من تاريخ 12 ديسمبر | V41: Present | W41: Absent | X41: Present | Y41: Absent | Z41: Present | AA41: Present | AB41: Present | AC41: =COUNTIF(E41:AB41,"Absent") | AD41: =COUNTIF(E41:AB41,"Present") | AE41: =(AD41*5)+(AC41*-5)
E42: Present | F42: Present | G42: Present | H42: Absent | I42: Present | J42: Present | K42: Present | L42: Present | M42: Present | N42: Present | O42: Absent | P42: Present | Q42: Present | R42: Absent | S42: Absent | T42: Present | U42: Absent | V42: Present | W42: Present | X42: Absent | Y42: Present | Z42: Present | AA42: Absent | AB42: Excused absence | AC42: Present | AD42: Absent | AE42: Present

Sheet Attendance 12 FEMALES
A1: SN | B1: Name (English) | C1: Name (Arabic) | D1: Academic ID | E1: 45931 | F1: 45936 | G1: 45937 | H1: 45938 | I1: 45943 | J1: 45945 | K1: 45950 | L1: 45952 | M1: 45957 | N1: 45959 | O1: 45964 | P1: 45966 | Q1: 45971 | R1: 45973 | S1: 45992 | T1: 45994 | U1: 45999 | V1: 46001 | W1: 46006 | X1: 46008 | Y1: 46013 | Z1: 46015 | AA1: 46020 | AB1: 45961 | AC1: Total Absent | AD1: Total Attendence | AE1: Total Points
A2: 1 | B2: Isra Hassan Salem Ayman | C2: إسراء حسن سالم أيمن | D2: 335072239 | E2: Present | F2: Present | G2: Excused absence | H2: Present | I2: Present | J2: Absent | K2: Present | L2: Present | M2: Present | N2: Present | O2: Absent | P2: Present | Q2: Present | R2: Present | S2: Absent | T2: Absent | U2: Absent | V2: Present | W2: Absent | X2: Present | Y2: Absent | Z2: Present | AA2: Present | AB2: Present | AC2: =COUNTIF(E2:AB2,"Absent") | AD2: =COUNTIF(E2:AB2,"Present") | AE2: =(AD2*5)+(AC2*-5)
A3: 2 | B3: Maha Faisal Saud Hussein | C3: مها فيصل سعود حسين | D3: 372255186 | E3: Present | F3: Present | G3: Present | H3: Present | I3: Present | J3: Present | K3: Absent | L3: Present | M3: Present | N3: Present | O3: Absent | P3: Present | Q3: Present | R3: Present | S3: Absent | T3: Present | U3: Present | V3: Present | W3: Absent | X3: Present | Y3: Present | Z3: Present | AA3: Absent | AB3: Present | AC3: =COUNTIF(E3:AB3,"Absent") | AD3: =COUNTIF(E3:AB3,"Present") | AE3: =(AD3*5)+(AC3*-5)
A4: 3 | B4: Haneen Faris Bassam Tariq | C4: حنين فارس بسام طارق | D4: 409438133 | E4: Present | F4: Present | G4: Present | H4: Present | I4: Present | J4: Present | K4: Present | L4: Present | M4: Present | N4: Present | O4: Present | P4: Present | Q4: Present | R4: Present | S4: Absent | T4: Absent | U4: Present | V4: Present | W4: Present | X4: Absent | Y4: Present | Z4: Absent | AA4: Present | AB4: Present | AC4: =COUNTIF(E4:AB4,"Absent") | AD4: =COUNTIF(E4:AB4,"Present") | AE4: =(AD4*5)+(AC4*-5)
A5: 4 | B5: Hoor Muath Mohannad Badr | C5: حور معاذ مهند بدر | D5: 446621080 | E5: Present | F5: Present | G5: Present | H5: Present | I5: Present | J5: Present | K5: Present | L5: Present | M5: Present | N5: Present | O5: Present | P5: Absent | Q5: Present | R5: Present | S5: Absent | T5: Absent | U5: Present | V5: Present | W5: Absent | X5: Present | Y5: Present | Z5: Present | AA5: Excused absence | AB5: Present | AC5: =COUNTIF(E5:AB5,"Absent") | AD5: =COUNTIF(E5:AB5,"Present") | AE5: =(AD5*5)+(AC5*-5)
A6: 5 | B6: Lana Hassan Saad Abdulmalik | C6: لانا حسن سعد عبدالملك | D6: 483804027 | E6: Excused absence | F6: Present | G6: Absent | H6: Present | I6: Present | J6: Present | K6: Present | L6: Present | M6: Present | N6: Present | O6: Present | P6: Present | Q6: Present | R6: Present | S6: Present | T6: Absent | U6: Present | V6: Absent | W6: Present | X6: Present | Y6: Present | Z6: Present | AA6: Absent | AB6: Present | AC6: =COUNTIF(E6:AB6,"Absent") | AD6: =COUNTIF(E6:AB6,"Present") | AE6: =(AD6*5)+(AC6*-5)
A7: 6 | B7: Muneerah Saqr Abdullah Saad | C7: منيرة صقر عبدالله سعد | D7: 520986974 | E7: Present | F7: Excused absence | G7: Absent | H7: Present | I7: Absent | J7: Present | K7: Present | L7: Absent | M7: Present | N7: Present | O7: Absent | P7: Present | Q7: Absent | R7: Absent | S7: Absent | T7: Absent | U7: Absent | V7: Absent | W7: Absent | X7: Present | Y7: Present | Z7: Present | AA7: Excused absence | AB7: Absent | AC7: =COUNTIF(E7:AB7,"Absent") | AD7: =COUNTIF(E7:AB7,"Present") | AE7: =(AD7*5)+(AC7*-5)
A8: 7 | B8: Mashael Hamad Tariq Yousef | C8: مشاعل حمد طارق يوسف | D8: 558169921 | E8: Excused absence | F8: Present | G8: Absent | H8: Present | I8: Absent | J8: Present | K8: Present | L8: Absent | M8: Present | N8: Present | O8: Present | P8: Absent | Q8: Present | R8: Present | S8: Present | T8: Absent | U8: Present | V8: Absent | W8: Absent | X8: Absent | Y8: Present | Z8: Present | AA8: Present | AB8: Absent | AC8: =COUNTIF(E8:AB8,"Absent") | AD8: =COUNTIF(E8:AB8,"Present") | AE8: =(AD8*5)+(AC8*-5)
A9: 8 | B9: Maha Salman Hazem Saad | C9: مها سلمان حازم سعد | D9: 595352868 | E9: Present | F9: Present | G9: Present | H9: Present | I9: Present | J9: Present | K9: Present | L9: Present | M9: Present | N9: Present | O9: Present | P9: Present | Q9: Present | R9: Present | S9: Absent | T9: Present | U9: Absent | V9: Present | W9: Absent | X9: Present | Y9: Absent | Z9: Present | AA9: Absent | AB9: Present | AC9: =COUNTIF(E9:AB9,"Absent") | AD9: =COUNTIF(E9:AB9,"Present") | AE9: =(AD9*5)+(AC9*-5)
A10: 9 | B10: Ghala Thamer Ayman Tariq | C10: غلا ثامر أيمن طارق | D10: 632535815 | E10: Present | F10: Present | G10: Present | H10: Present | I10: Present | J10: Present | K10: Present | L10: Present | M10: Absent | N10: Present | O10: Absent | P10: Absent | Q10: Present | R10: Present | S10: Absent | T10: Present | U10: Absent | V10: Absent | W10: Absent | X10: Absent | Y10: Present | Z10: Present | AA10: Present | AB10: Present | AC10: =COUNTIF(E10:AB10,"Absent") | AD10: =COUNTIF(E10:AB10,"Present") | AE10: =(AD10*5)+(AC10*-5)
A11: 10 | B11: Dima Muath Fawaz Hamed | C11: ديما معاذ فواز حامد | D11: 669718762 | E11: Present | F11: Excused absence | G11: Present | H11: Present | I11: Present | J11: Present | K11: Absent | L11: Absent | M11: Present | N11: Absent | O11: Present | P11: Absent | Q11: Present | R11: Absent | S11: Present | T11: Absent | U11: Present | V11: Present | W11: Present | X11: Present | Y11: Present | Z11: Present | AA11: Present | AB11: Excused absence | AC11: =COUNTIF(E11:AB11,"Absent") | AD11: =COUNTIF(E11:AB11,"Present") | AE11: =(AD11*5)+(AC11*-5)
A12: 11 | B12: Latifah Yazeed Adnan Mohammed | C12: لطيفة يزيد عدنان محمد | D12: 706901709 | E12: Present | F12: Absent | G12: Present | H12: Present | I12: Present | J12: Present | K12: Present | L12: Present | M12: Present | N12: Absent | O12: Absent | P12: Absent | Q12: Absent | R12: Present | S12: Present | T12: Present | U12: Absent | V12: Absent | W12: Absent | X12: Present | Y12: Present | Z12: Present | AA12: Absent | AB12: Present | AC12: =COUNTIF(E12:AB12,"Absent") | AD12: =COUNTIF(E12:AB12,"Present") | AE12: =(AD12*5)+(AC12*-5)
A13: 12 | B13: Asmaa Mohannad Mansour Ayman | C13: أسماء مهند منصور أيمن | D13: 744084656 | E13: Present | F13: Present | G13: Absent | H13: Present | I13: Present | J13: Present | K13: Present | L13: Present | M13: Present | N13: Present | O13: Present | P13: Present | Q13: Present | R13: Present | S13: Present | T13: Present | U13: Absent | V13: Present | W13: Absent | X13: Present | Y13: Present | Z13: Present | AA13: Present | AB13: Absent | AC13: =COUNTIF(E13:AB13,"Absent") | AD13: =COUNTIF(E13:AB13,"Present") | AE13: =(AD13*5)+(AC13*-5)
... A34: 33 | B34: Sarah Tariq Hazem Munther | C34: سارة طارق حازم منذر | D34: 524926543 | E34: Absent | F34: Absent | G34: Present | H34: Present | I34: Present | J34: Present | K34: Present | L34: Absent | M34: Present | N34: Present | O34: Absent | P34: Absent | Q34: Absent | R34: Absent | S34: Absent | T34: Absent | U34: Present | V34: Present | W34: Absent | X34: Excused absence | Y34: Present | Z34: Present | AA34: Present | AB34: Absent | AC34: =COUNTIF(E34:AB34,"Absent") | AD34: =COUNTIF(E34:AB34,"Present") | AE34: =(AD34*5)+(AC34*-5)
B35: Hatoon Abdulmalik Muath Badr | C35: هتون عبدالملك معاذ بدر | D35: 562109490 | E35: إضافـــــــــــــــــــــــــــــــــــــــــة جديدة من 3 ديسمبر | T35: Present | U35: Absent | V35: Absent | W35: Absent | X35: Absent | Y35: Present | Z35: Present | AA35: Present | AB35: Present | AC35: =COUNTIF(E35:AB35,"Absent") | AD35: =COUNTIF(E35:AB35,"Present") | AE35: =(AD35*5)+(AC35*-5)
B36: Moudi Turki Adel Ayman | C36: موضي تركي عادل أيمن | D36: 599292437 | T36: Present | U36: Absent | V36: Absent | W36: Present | X36: Present | Y36: Absent | Z36: Absent | AA36: Present | AB36: Present | AC36: =COUNTIF(E36:AB36,"Absent") | AD36: =COUNTIF(E36:AB36,"Present") | AE36: =(AD36*5)+(AC36*-5)
E37: Present | F37: Present | G37: Absent | H37: Present | I37: Present | J37: Present | K37: Present | L37: Present | M37: Present | N37: Present | O37: Present | P37: Present | Q37: Absent | R37: Absent | S37: Present | T37: Present | U37: Present | V37: Present | W37: Absent | X37: Present | Y37: Excused absence | Z37: Present | AA37: Present | AB37: Absent | AC37: Present | AD37: Present | AE37: Present

Sheet Attendance 10 MALES
A1: SN | B1: Name (English) | C1: Name (Arabic) | D1: Academic ID | E1: 45931 | F1: 45936 | G1: 45937 | H1: 45938 | I1: 45943 | J1: 45945 | K1: 45950 | L1: 45952 | M1: 45957 | N1: 45959 | O1: 45964 | P1: 45966 | Q1: 45971 | R1: 45973 | S1: 45992 | T1: 45994 | U1: 45999 | V1: 46001 | W1: 46006 | X1: 46008 | Y1: 46013 | Z1: 46015 | AA1: 46020 | AB1: 45961 | AC1: Total Absent | AD1: Total Attendence | AE1: Total Points
A2: 1 | B2: Hamad Ahmed Nawaf Mohannad | C2: حمد أحمد نواف مهند | D2: 332072239 | E2: Present | F2: Present | G2: Present | H2: Present | I2: Present | J2: Present | K2: Present | L2: Present | M2: Present | N2: Present | O2: Absent | P2: Present | Q2: Absent | R2: Present | S2: Present | T2: Present | U2: Present | V2: Present | W2: Present | X2: Present | Y2: Present | Z2: Present | AA2: Present | AB2: Present | AC2: =COUNTIF(E2:AB2,"Absent") | AD2: =COUNTIF(E2:AB2,"Present") | AE2: =(AD2*5)+(AC2*-5)
A3: 2 | B3: Majed Mohammed Salman Marwan | C3: ماجد محمد سلمان مروان | D3: 369255186 | E3: Present | F3: Absent | G3: Present | H3: Absent | I3: Present | J3: Present | K3: Absent | L3: Absent | M3: Present | N3: Absent | O3: Absent | P3: Absent | Q3: Absent | R3: Absent | S3: Absent | T3: Absent | U3: Absent | V3: Absent | W3: Absent | X3: Present | Y3: Present | Z3: Present | AA3: Present | AB3: Present | AC3: =COUNTIF(E3:AB3,"Absent") | AD3: =COUNTIF(E3:AB3,"Present") | AE3: =(AD3*5)+(AC3*-5)
A4: 3 | B4: Adnan Munther Abdullah Majed | C4: عدنان منذر عبدالله ماجد | D4: 406438133 | E4: Present | F4: Present | G4: Present | H4: Present | I4: Present | J4: Present | K4: Present | L4: Present | M4: Present | N4: Present | O4: Present | P4: Present | Q4: Absent | R4: Present | S4: Absent | T4: Absent | U4: Present | V4: Present | W4: Absent | X4: Present | Y4: Present | Z4: Present | AA4: Present | AB4: Present | AC4: =COUNTIF(E4:AB4,"Absent") | AD4: =COUNTIF(E4:AB4,"Present") | AE4: =(AD4*5)+(AC4*-5)
A5: 4 | B5: Abdulmalik Nasser Ahmed Abdulmalik | C5: عبدالملك ناصر أحمد عبدالملك | D5: 443621080 | E5: Present | F5: Present | G5: Present | H5: Present | I5: Absent | J5: Present | K5: Present | L5: Present | M5: Absent | N5: Present | O5: Present | P5: Present | Q5: Present | R5: Present | S5: Absent | T5: Present | U5: Absent | V5: Present | W5: Absent | X5: Present | Y5: Present | Z5: Present | AA5: Present | AB5: Present | AC5: =COUNTIF(E5:AB5,"Absent") | AD5: =COUNTIF(E5:AB5,"Present") | AE5: =(AD5*5)+(AC5*-5)
A6: 5 | B6: Iyad Basheer Omar Saud | C6: إياد بشير عمر سعود | D6: 480804027 | E6: Absent | F6: Absent | G6: Present | H6: Absent | I6: Present | J6: Present | K6: Present | L6: Present | M6: Absent | N6: Present | O6: Present | P6: Present | Q6: Present | R6: Present | S6: Absent | T6: Absent | U6: Absent | V6: Absent | W6: Absent | X6: Present | Y6: Present | Z6: Present | AA6: Present | AB6: Present | AC6: =COUNTIF(E6:AB6,"Absent") | AD6: =COUNTIF(E6:AB6,"Present") | AE6: =(AD6*5)+(AC6*-5)
A7: 6 | B7: Khalid Ali Saad Tariq | C7: خالد علي سعد طارق | D7: 517986974 | E7: Present | F7: Present | G7: Absent | H7: Present | I7: Present | J7: Present | K7: Present | L7: Present | M7: Present | N7: Present | O7: Present | P7: Present | Q7: Present | R7: Present | S7: Absent | T7: Present | U7: Present | V7: Present | W7: Present | X7: Present | Y7: Present | Z7: Present | AA7: Present | AB7: Present | AC7: =COUNTIF(E7:AB7,"Absent") | AD7: =COUNTIF(E7:AB7,"Present") | AE7: =(AD7*5)+(AC7*-5)
A8: 7 | B8: Marwan Munther Hamad Nayef | C8: مروان منذر حمد نايف | D8: 555169921 | E8: Present | F8: Absent | G8: Present | H8: Present | I8: Present | J8: Present | K8: Present | L8: Present | M8: Present | N8: Present | O8: Absent | P8: Present | Q8: Present | R8: Present | S8: Absent | T8: Absent | U8: Present | V8: Absent | W8: Absent | X8: Present | Y8: Present | Z8: Present | AA8: Present | AB8: Present | AC8: =COUNTIF(E8:AB8,"Absent") | AD8: =COUNTIF(E8:AB8,"Present") | AE8: =(AD8*5)+(AC8*-5)
A9: 8 | B9: Jihad Saad Mohannad Mohammed | C9: جهاد سعد مهند محمد | D9: 592352868 | E9: Present | F9: Excused absence | G9: Present | H9: Present | I9: Present | J9: Excused absence | K9: Present | L9: Absent | M9: Absent | N9: Present | O9: Present | P9: Present | Q9: Absent | R9: Present | S9: Present | T9: Present | U9: Absent | V9: Present | W9: Present | X9: Present | Y9: Present | Z9: Present | AA9: Present | AB9: Present | AC9: =COUNTIF(E9:AB9,"Absent") | AD9: =COUNTIF(E9:AB9,"Present") | AE9: =(AD9*5)+(AC9*-5)
A10: 9 | B10: Anas Khalid Faris Saad | C10: أنس خالد فارس سعد | D10: 629535815 | E10: Present | F10: Present | G10: Present | H10: Present | I10: Present | J10: Present | K10: Present | L10: Present | M10: Present | N10: Absent | O10: Absent | P10: Present | Q10: Present | R10: Present | S10: Absent | T10: Absent | U10: Present | V10: Present | W10: Present | X10: Present | Y10: Present | Z10: Present | AA10: Present | AB10: Present | AC10: =COUNTIF(E10:AB10,"Absent") | AD10: =COUNTIF(E10:AB10,"Present") | AE10: =(AD10*5)+(AC10*-5)
A11: 10 | B11: Ibrahim Sami Nawaf Badr | C11: إبراهيم سامي نواف بدر | D11: 666718762 | E11: Present | F11: Present | G11: Present | H11: Present | I11: Present | J11: Present | K11: Present | L11: Present | M11: Present | N11: Absent | O11: Present | P11: Present | Q11: Present | R11: Present | S11: Absent | T11: Absent | U11: Absent | V11: Absent | W11: Absent | X11: Present | Y11: Present | Z11: Present | AA11: Present | AB11: Present | AC11: =COUNTIF(E11:AB11,"Absent") | AD11: =COUNTIF(E11:AB11,"Present") | AE11: =(AD11*5)+(AC11*-5)
A12: 11 | B12: Tamim Rami Abdulaziz Muath | C12: تميم رامي عبدالعزيز معاذ | D12: 703901709 | E12: Present | F12: Present | G12: Present | H12: Present | I12: Present | J12: Present | K12: Present | L12: Present | M12: Present | N12: Present | O12: Present | P12: Absent | Q12: Present | R12: Present | S12: Present | T12: Present | U12: Present | V12: Present | W12: Absent | X12: Present | Y12: Present | Z12: Present | AA12: Present | AB12: Present | AC12: =COUNTIF(E12:AB12,"Absent") | AD12: =COUNTIF(E12:AB12,"Present") | AE12: =(AD12*5)+(AC12*-5)
A13: 12 | B13: Ahmed Hadi Yasser Abdulrahman | C13: أحمد هادي ياسر عبدالرحمن | D13: 741084656 | E13: Present | F13: Present | G13: Present | H13: Excused absence | I13: Present | J13: Present | K13: Absent | L13: Absent | M13: Absent | N13: Absent | O13: Absent | P13: Absent | Q13: Absent | R13: Absent | S13: Absent | T13: Absent | U13: Absent | V13: Absent | W13: Absent | X13: Present | Y13: Present | Z13: Present | AA13: Present | AB13: Present | AC13: =COUNTIF(E13:AB13,"Absent") | AD13: =COUNTIF(E13:AB13,"Present") | AE13: =(AD13*5)+(AC13*-5)
... A38: 37 | B38: Hassan Mazen Faris Adel | C38: حسن مازن فارس عادل | D38: 670658331 | E38: Excused absence | F38: Present | G38: Present | H38: Absent | I38: Absent | J38: Absent | K38: Present | L38: Present | M38: Present | N38: Present | O38: Present | P38: Present | Q38: Present | R38: Present | S38: Absent | T38: Present | U38: Present | V38: Present | W38: Present | X38: Present | Y38: Present | Z38: Present | AA38: Present | AB38: Present | AC38: =COUNTIF(E38:AB38,"Absent") | AD38: =COUNTIF(E38:AB38,"Present") | AE38: =(AD38*5)+(AC38*-5)

Sheet Attendance 11 MALES
A1: SN | B1: Name (English) | C1: Name (Arabic) | D1: Academic ID | E1: 45931 | F1: 45936 | G1: 45937 | H1: 45938 | I1: 45943 | J1: 45945 | K1: 45950 | L1: 45952 | M1: 45957 | N1: 45959 | O1: 45964 | P1: 45966 | Q1: 45971 | R1: 45973 | S1: 45992 | T1: 45994 | U1: 45999 | V1: 46001 | W1: 46006 | X1: 46008 | Y1: 46013 | Z1: 46015 | AA1: 46020 | AB1: 45961 | AC1: Total Absent | AD1: Total Attendence | AE1: Total Points
A2: 1 | B2: Nawaf Tamim Sami Omar | C2: نواف تميم سامي عمر | D2: 334072239 | E2: Present | F2: Present | G2: Present | H2: Present | I2: Present | J2: Present | K2: Present | L2: Present | M2: Absent | N2: Present | O2: Present | P2: Present | Q2: Present | R2: Present | S2: Absent | T2: Absent | U2: Absent | V2: Present | W2: Absent | X2: Absent | Y2: Absent | Z2: Excused absence | AA2: Absent | AB2: Present | AC2: =COUNTIF(E2:AB2,"Absent") | AD2: =COUNTIF(E2:AB2,"Present") | AE2: =(AD2*5)+(AC2*-5)
A3: 2 | B3: Mishari Saif Mohannad Hazem | C3: مشاري سيف مهند حازم | D3: 371255186 | E3: Present | F3: Present | G3: Absent | H3: Present | I3: Present | J3: Absent | K3: Present | L3: Present | M3: Present | N3: Present | O3: Present | P3: Present | Q3: Present | R3: Absent | S3: Absent | T3: Present | U3: Absent | V3: Present | W3: Absent | X3: Absent | Y3: Present | Z3: Present | AA3: Present | AB3: Present | AC3: =COUNTIF(E3:AB3,"Absent") | AD3: =COUNTIF(E3:AB3,"Present") | AE3: =(AD3*5)+(AC3*-5)
A4: 3 | B4: Omar Iyad Fahad Hussein | C4: عمر إياد فهد حسين | D4: 408438133 | E4: Present | F4: Absent | G4: Absent | H4: Present | I4: Present | J4: Present | K4: Present | L4: Present | M4: Present | N4: Absent | O4: Present | P4: Present | Q4: Absent | R4: Absent | S4: Absent | T4: Absent | U4: Absent | V4: Absent | W4: Absent | X4: Present | Y4: Present | Z4: Present | AA4: Present | AB4: Present | AC4: =COUNTIF(E4:AB4,"Absent") | AD4: =COUNTIF(E4:AB4,"Present") | AE4: =(AD4*5)+(AC4*-5)
A5: 4 | B5: Tariq Sultan Saleh Mishari | C5: طارق سلطان صالح مشاري | D5: 445621080 | E5: Absent | F5: Present | G5: Absent | H5: Absent | I5: Absent | J5: Present | K5: Absent | L5: Absent | M5: Present | N5: Absent | O5: Absent | P5: Present | Q5: Absent | R5: Absent | S5: Absent | T5: Absent | U5: Present | V5: Absent | W5: Absent | X5: Present | Y5: Absent | Z5: Present | AA5: Present | AB5: Present | AC5: =COUNTIF(E5:AB5,"Absent") | AD5: =COUNTIF(E5:AB5,"Present") | AE5: =(AD5*5)+(AC5*-5)
A6: 5 | B6: Salem Saud Abdulmajid Mansour | C6: سالم سعود عبدالمجيد منصور | D6: 482804027 | E6: Present | F6: Absent | G6: Present | H6: Present | I6: Present | J6: Present | K6: Absent | L6: Present | M6: Present | N6: Present | O6: Present | P6: Absent | Q6: Present | R6: Present | S6: Absent | T6: Present | U6: Absent | V6: Present | W6: Present | X6: Present | Y6: Excused absence | Z6: Present | AA6: Absent | AB6: Present | AC6: =COUNTIF(E6:AB6,"Absent") | AD6: =COUNTIF(E6:AB6,"Present") | AE6: =(AD6*5)+(AC6*-5)
A7: 6 | B7: Anas Badr Jihad Saad | C7: أنس بدر جهاد سعد | D7: 519986974 | E7: Present | F7: Present | G7: Present | H7: Present | I7: Absent | J7: Present | K7: Present | L7: Present | M7: Present | N7: Present | O7: Present | P7: Present | Q7: Present | R7: Absent | S7: Absent | T7: Absent | U7: Absent | V7: Absent | W7: Absent | X7: Present | Y7: Present | Z7: Present | AA7: Present | AB7: Absent | AC7: =COUNTIF(E7:AB7,"Absent") | AD7: =COUNTIF(E7:AB7,"Present") | AE7: =(AD7*5)+(AC7*-5)
A8: 7 | B8: Muath Rashid Saif Jihad | C8: معاذ راشد سيف جهاد | D8: 557169921 | E8: Present | F8: Absent | G8: Present | H8: Present | I8: Present | J8: Present | K8: Present | L8: Present | M8: Present | N8: Present | O8: Present | P8: Absent | Q8: Absent | R8: Present | S8: Absent | T8: Present | U8: Absent | V8: Present | W8: Absent | X8: Present | Y8: Absent | Z8: Present | AA8: Excused absence | AB8: Present | AC8: =COUNTIF(E8:AB8,"Absent") | AD8: =COUNTIF(E8:AB8,"Present") | AE8: =(AD8*5)+(AC8*-5)
A9: 8 | B9: Adel Ayman Abdulaziz Muath | C9: عادل أيمن عبدالعزيز معاذ | D9: 594352868 | E9: Present | F9: Present | G9: Present | H9: Present | I9: Present | J9: Present | K9: Present | L9: Present | M9: Present | N9: Present | O9: Present | P9: Absent | Q9: Present | R9: Present | S9: Present | T9: Present | U9: Absent | V9: Absent | W9: Absent | X9: Present | Y9: Absent | Z9: Present | AA9: Present | AB9: Absent | AC9: =COUNTIF(E9:AB9,"Absent") | AD9: =COUNTIF(E9:AB9,"Present") | AE9: =(AD9*5)+(AC9*-5)
A10: 9 | B10: Yousef Muath Yasser Saif | C10: يوسف معاذ ياسر سيف | D10: 631535815 | E10: Present | F10: Present | G10: Present | H10: Present | I10: Present | J10: Present | K10: Present | L10: Present | M10: Present | N10: Present | O10: Present | P10: Present | Q10: Absent | R10: Absent | S10: Present | T10: Present | U10: Absent | V10: Absent | W10: Absent | X10: Present | Y10: Present | Z10: Present | AA10: Absent | AB10: Present | AC10: =COUNTIF(E10:AB10,"Absent") | AD10: =COUNTIF(E10:AB10,"Present") | AE10: =(AD10*5)+(AC10*-5)
A11: 10 | B11: Ibrahim Rami Jassim Badr | C11: إبراهيم رامي جاسم بدر | D11: 668718762 | E11: Present | F11: Present | G11: Present | H11: Present | I11: Present | J11: Present | K11: Present | L11: Present | M11: Present | N11: Present | O11: Present | P11: Present | Q11: Present | R11: Present | S11: Present | T11: Present | U11: Present | V11: Present | W11: Absent | X11: Present | Y11: Present | Z11: Absent | AA11: Absent | AB11: Present | AC11: =COUNTIF(E11:AB11,"Absent") | AD11: =COUNTIF(E11:AB11,"Present") | AE11: =(AD11*5)+(AC11*-5)
A12: 11 | B12: Abdullah Saleh Basheer Rashid | C12: عبدالله صالح بشير راشد | D12: 705901709 | E12: Present | F12: Present | G12: Present | H12: Present | I12: Present | J12: Present | K12: Present | L12: Present | M12: Present | N12: Absent | O12: Present | P12: Present | Q12: Absent | R12: Present | S12: Present | T12: Present | U12: Absent | V12: Present | W12: Absent | X12: Absent | Y12: Present | Z12: Present | AA12: Present | AB12: Present | AC12: =COUNTIF(E12:AB12,"Absent") | AD12: =COUNTIF(E12:AB12,"Present") | AE12: =(AD12*5)+(AC12*-5)
A13: 12 | B13: Majed Majed Abdulmalik Adel | C13: ماجد ماجد عبدالملك عادل | D13: 743084656 | E13: Excused absence | F13: Present | G13: Present | H13: Present | I13: Present | J13: Present | K13: Absent | L13: Present | M13: Present | N13: Present | O13: Present | P13: Present | Q13: Present | R13: Present | S13: Absent | T13: Absent | U13: Present | V13: Present | W13: Present | X13: Absent | Y13: Present | Z13: Present | AA13: Absent | AB13: Present | AC13: =COUNTIF(E13:AB13,"Absent") | AD13: =COUNTIF(E13:AB13,"Present") | AE13: =(AD13*5)+(AC13*-5)
... A41: 40 | B41: Iyad Salman Rakan Badr | C41: إياد سلمان راكان بدر | D41: 747024225 | E41: Present | F41: Present | G41: Present | H41: Present | I41: Present | J41: Present | K41: Present | L41: Absent | M41: Present | N41: Absent | O41: Present | P41: Present | Q41: Present | R41: Present | S41: Present | T41: Present | U41: Present | V41: Present | W41: Absent | X41: Present | Y41: Present | Z41: Present | AA41: Present | AB41: Absent | AC41: =COUNTIF(E41:AB41,"Absent") | AD41: =COUNTIF(E41:AB41,"Present") | AE41: =(AD41*5)+(AC41*-5)
E42: Present | F42: Present | G42: Present | H42: Absent | I42: Present | J42: Absent | K42: Present | L42: Absent | M42: Present | N42: Present | O42: Excused absence | P42: Present | Q42: Present | R42: Present | S42: Absent | T42: Present | U42: Absent | V42: Absent | W42: Present | X42: Present | Y42: Present | Z42: Absent | AA42: Present | AB42: Present | AC42: Present | AD42: Present | AE42: Absent

Sheet Attendance 12 MALES
A1: SN | B1: Name (English) | C1: Name (Arabic) | D1: Academic ID | E1: 45931 | F1: 45936 | G1: 45937 | H1: 45938 | I1: 45943 | J1: 45945 | K1: 45950 | L1: 45952 | M1: 45957 | N1: 45959 | O1: 45964 | P1: 45966 | Q1: 45971 | R1: 45973 | S1: 45992 | T1: 45994 | U1: 45999 | V1: 46001 | W1: 46006 | X1: 46008 | Y1: 46013 | Z1: 46015 | AA1: 46020 | AB1: 45961 | AC1: Total Absent | AD1: Total Attendence | AE1: Total Points
A2: 1 | B2: Ibrahim Adel Marwan Majed | C2: إبراهيم عادل مروان ماجد | D2: 336072239 | E2: Present | F2: Present | G2: Present | H2: Excused absence | I2: Present | J2: Absent | K2: Present | L2: Present | M2: Present | N2: Absent | O2: Present | P2: Absent | Q2: Present | R2: Absent | S2: Absent | T2: Present | U2: Absent | V2: Absent | W2: Absent | X2: Present | Y2: Absent | Z2: Present | AA2: Present | AB2: Present | AC2: =COUNTIF(E2:AB2,"Absent") | AD2: =COUNTIF(E2:AB2,"Present") | AE2: =(AD2*5)+(AC2*-5)
A3: 2 | B3: Bandar Iyad Waleed Adnan | C3: بندر إياد وليد عدنان | D3: 373255186 | E3: Present | F3: Excused absence | G3: Present | H3: Excused absence | I3: Present | J3: Present | K3: Present | L3: Present | M3: Present | N3: Absent | O3: Absent | P3: Present | Q3: Present | R3: Present | S3: Present | T3: Absent | U3: Present | V3: Present | W3: Present | X3: Absent | Y3: Present | Z3: Present | AA3: Absent | AB3: Absent | AC3: =COUNTIF(E3:AB3,"Absent") | AD3: =COUNTIF(E3:AB3,"Present") | AE3: =(AD3*5)+(AC3*-5)
A4: 3 | B4: Sami Yazeed Munther Saleh | C4: سامي يزيد منذر صالح | D4: 410438133 | E4: Absent | F4: Absent | G4: Present | H4: Present | I4: Present | J4: Absent | K4: Absent | L4: Absent | M4: Absent | N4: Absent | O4: Absent | P4: Absent | Q4: Absent | R4: Absent | S4: Absent | T4: Absent | U4: Present | V4: Absent | W4: Absent | X4: Present | Y4: Present | Z4: Present | AA4: Absent | AB4: Present | AC4: =COUNTIF(E4:AB4,"Absent") | AD4: =COUNTIF(E4:AB4,"Present") | AE4: =(AD4*5)+(AC4*-5)
A5: 4 | B5: Thamer Saif Nayef Hamad | C5: ثامر سيف نايف حمد | D5: 447621080 | E5: Absent | F5: Absent | G5: Present | H5: Present | I5: Absent | J5: Absent | K5: Absent | L5: Present | M5: Absent | N5: Absent | O5: Absent | P5: Absent | Q5: Absent | R5: Present | S5: Absent | T5: Absent | U5: Absent | V5: Absent | W5: Absent | X5: Present | Y5: Present | Z5: Present | AA5: Present | AB5: Present | AC5: =COUNTIF(E5:AB5,"Absent") | AD5: =COUNTIF(E5:AB5,"Present") | AE5: =(AD5*5)+(AC5*-5)
A6: 5 | B6: Bandar Hussam Rashid Ayman | C6: بندر حسام راشد أيمن | D6: 484804027 | E6: Excused absence | F6: Present | G6: Absent | H6: Present | I6: Absent | J6: Present | K6: Present | L6: Absent | M6: Present | N6: Present | O6: Absent | P6: Absent | Q6: Present | R6: Absent | S6: Present | T6: Present | U6: Present | V6: Absent | W6: Present | X6: Present | Y6: Present | Z6: Excused absence | AA6: Present | AB6: Present | AC6: =COUNTIF(E6:AB6,"Absent") | AD6: =COUNTIF(E6:AB6,"Present") | AE6: =(AD6*5)+(AC6*-5)
A7: 6 | B7: Yazeed Waleed Ali Saad | C7: يزيد وليد علي سعد | D7: 521986974 | E7: Present | F7: Present | G7: Absent | H7: Excused absence | I7: Present | J7: Excused absence | K7: Present | L7: Present | M7: Present | N7: Absent | O7: Present | P7: Absent | Q7: Present | R7: Present | S7: Absent | T7: Present | U7: Absent | V7: Absent | W7: Absent | X7: Present | Y7: Present | Z7: Present | AA7: Present | AB7: Present | AC7: =COUNTIF(E7:AB7,"Absent") | AD7: =COUNTIF(E7:AB7,"Present") | AE7: =(AD7*5)+(AC7*-5)
A8: 7 | B8: Yousef Salem Badr Abdullah | C8: يوسف سالم بدر عبدالله | D8: 559169921 | E8: Present | F8: Present | G8: Present | H8: Present | I8: Present | J8: Present | K8: Present | L8: Present | M8: Present | N8: Present | O8: Present | P8: Absent | Q8: Present | R8: Present | S8: Present | T8: Present | U8: Absent | V8: Present | W8: Absent | X8: Present | Y8: Absent | Z8: Absent | AA8: Present | AB8: Present | AC8: =COUNTIF(E8:AB8,"Absent") | AD8: =COUNTIF(E8:AB8,"Present") | AE8: =(AD8*5)+(AC8*-5)
A9: 8 | B9: Abdulaziz Marwan Salem Nayef | C9: عبدالعزيز مروان سالم نايف | D9: 596352868 | E9: Present | F9: Present | G9: Present | H9: Excused absence | I9: Present | J9: Present | K9: Present | L9: Present | M9: Present | N9: Present | O9: Present | P9: Absent | Q9: Absent | R9: Present | S9: Present | T9: Present | U9: Present | V9: Absent | W9: Absent | X9: Absent | Y9: Present | Z9: Absent | AA9: Present | AB9: Present | AC9: =COUNTIF(E9:AB9,"Absent") | AD9: =COUNTIF(E9:AB9,"Present") | AE9: =(AD9*5)+(AC9*-5)
A10: 9 | B10: Yousef Marzouq Badr Hussam | C10: يوسف مرزوق بدر حسام | D10: 633535815 | E10: Present | F10: Present | G10: Present | H10: Excused absence | I10: Present | J10: Excused absence | K10: Present | L10: Absent | M10: Present | N10: Present | O10: Absent | P10: Absent | Q10: Present | R10: Absent | S10: Absent | T10: Absent | U10: Absent | V10: Present | W10: Absent | X10: Present | Y10: Absent | Z10: Present | AA10: Absent | AB10: Present | AC10: =COUNTIF(E10:AB10,"Absent") | AD10: =COUNTIF(E10:AB10,"Present") | AE10: =(AD10*5)+(AC10*-5)
A11: 10 | B11: Rayan Yazeed Muath Nasser | C11: ريان يزيد معاذ ناصر | D11: 670718762 | E11: Absent | F11: Present | G11: Present | H11: Absent | I11: Absent | J11: Absent | K11: Present | L11: Absent | M11: Present | N11: Absent | O11: Present | P11: Present | Q11: Absent | R11: Absent | S11: Absent | T11: Absent | U11: Absent | V11: Absent | W11: Absent | X11: Present | Y11: Absent | Z11: Absent | AA11: Present | AB11: Absent | AC11: =COUNTIF(E11:AB11,"Absent") | AD11: =COUNTIF(E11:AB11,"Present") | AE11: =(AD11*5)+(AC11*-5)
A12: 11 | B12: Munther Hadi Ayman Mohannad | C12: منذر هادي أيمن مهند | D12: 707901709 | E12: Present | F12: Present | G12: Present | H12: Absent | I12: Excused absence | J12: Present | K12: Present | L12: Present | M12: Present | N12: Present | O12: Absent | P12: Present | Q12: Present | R12: Present | S12: Absent | T12: Present | U12: Absent | V12: Absent | W12: Absent | X12: Excused absence | Y12: Present | Z12: Absent | AA12: Present | AB12: Present | AC12: =COUNTIF(E12:AB12,"Absent") | AD12: =COUNTIF(E12:AB12,"Present") | AE12: =(AD12*5)+(AC12*-5)
A13: 12 | B13: Badr Tariq Bassam Rayan | C13: بدر طارق بسام ريان | D13: 745084656 | E13: Present | F13: Present | G13: Present | H13: Present | I13: Present | J13: Excused absence | K13: Present | L13: Present | M13: Present | N13: Present | O13: Present | P13: Present | Q13: Present | R13: Present | S13: Absent | T13: Present | U13: Present | V13: Present | W13: Present | X13: Present | Y13: Absent | Z13: Present | AA13: Present | AB13: Absent | AC13: =COUNTIF(E13:AB13,"Absent") | AD13: =COUNTIF(E13:AB13,"Present") | AE13: =(AD13*5)+(AC13*-5)
... A33: 32 | B33: Munther Jaber Saqr Yasser | C33: منذر جابر صقر ياسر | D33: 488743596 | E33: Present | F33: Absent | G33: Present | H33: Present | I33: Present | J33: Present | K33: Absent | L33: Present | M33: Present | N33: Present | O33: Present | P33: Present | Q33: Present | R33: Present | S33: Present | T33: Present | U33: Absent | V33: Present | W33: Present | X33: Absent | Y33: Present | Z33: Present | AA33: Present | AB33: Present | AC33: =COUNTIF(E33:AB33,"Absent") | AD33: =COUNTIF(E33:AB33,"Present") | AE33: =(AD33*5)+(AC33*-5)
B34: Marzouq Mazen Saqr Abdulmalik | C34: مرزوق مازن صقر عبدالملك | D34: 525926543 | E34: Present | F34: Present | G34: Present | H34: Present | I34: Present | J34: Excused absence | K34: Absent | L34: Present | M34: Present | N34: Present | O34: Present | P34: Present | Q34: Absent | R34: Present | S34: Present | T34: Present | U34: Present | V34: Present | W34: Present | X34: Present | Y34: Excused absence | Z34: Absent | AA34: Present | AB34: Present | AC34: =COUNTIF(E34:AB34,"Absent") | AD34: =COUNTIF(E34:AB34,"Present") | AE34: =(AD34*5)+(AC34*-5)

Sheet Participation 10 FEMALES
A1: SN | B1: Name | C1: Name (Arabic) | D1: Academic ID | E1: Day-1 | F1: Day-2 | G1: Day-3 | H1: Day-4 | I1: Day-5 | J1: Day-6 | K1: Day-7 | L1: Day-8 | M1: Day-9 | N1: Day-10 | O1: Day-11 | P1: Day-12 | Q1: Day-13 | R1: Day-14 | S1: Day-15 | T1: Day-16 | U1: Day-17 | V1: Day-18 | W1: Day-19 | X1: Day-20 | Y1: Day-21 | Z1: Day-22 | AA1: Day-23 | AB1: Day-24 | AC1: Day-25 | AD1: Total
A2: 1 | B2: Maryam Nasser Khalid Yousef | C2: مريم ناصر خالد يوسف | D2: 331072239 | E2: 4 | F2: 9 | G2: 6 | H2: 5 | I2: 9 | J2: 3 | K2: 4 | L2: 10 | M2: 1 | N2: 2 | O2: 2 | P2: 0 | Q2: 2 | R2: 10 | S2: 10 | T2: 2 | U2: 7 | V2: 3 | W2: 3 | X2: 1 | Y2: 10 | Z2: 6 | AA2: 1 | AB2: 5 | AC2: 1 | AD2: =SUM(E2:AC2)
A3: 2 | B3: Amal Fahad Majed Marwan | C3: أمل فهد ماجد مروان | D3: 368255186 | E3: 7 | F3: 7 | G3: 8 | H3: 6 | I3: 6 | J3: 2 | K3: 3 | L3: 2 | M3: 8 | N3: 10 | O3: 3 | P3: 1 | Q3: 7 | R3: 2 | S3: 2 | T3: 2 | U3: 45 | V3: 4 | W3: 10 | X3: 2 | Y3: 2 | Z3: 10 | AA3: 3 | AB3: 0 | AC3: 1 | AD3: =SUM(E3:AC3)
A4: 3 | B4: Aljoharah Hussam Sultan Waleed | C4: الجوهرة حسام سلطان وليد | D4: 405438133 | E4: 6 | F4: 5 | G4: 6 | H4: 1 | I4: 9 | J4: 4 | K4: 6 | L4: 2 | M4: 9 | N4: 8 | O4: 4 | P4: 4 | Q4: 8 | R4: 7 | S4: 6 | T4: 2 | U4: 6 | V4: 4 | W4: 5 | X4: 10 | Y4: 8 | Z4: 3 | AA4: 1 | AB4: 7 | AC4: 9 | AD4: =SUM(E4:AC4)
A5: 4 | B5: Leen Ahmed Hussein Nawaf | C5: لين أحمد حسين نواف | D5: 442621080 | E5: 10 | F5: 8 | G5: 7 | H5: 6 | I5: 5 | J5: 0 | K5: 7 | L5: 7 | M5: 2 | N5: 6 | O5: 8 | P5: 4 | Q5: 6 | R5: 5 | S5: 2 | T5: 2 | U5: 6 | V5: 0 | W5: 3 | X5: 5 | Y5: 8 | Z5: 4 | AA5: 1 | AB5: 3 | AC5: 9 | AD5: =SUM(E5:AC5)
A6: 5 | B6: Ghina Omar Rayan Yazeed | C6: غنى عمر ريان يزيد | D6: 479804027 | E6: 9 | F6: 3 | G6: 9 | H6: 8 | I6: 2 | J6: 3 | K6: 10 | L6: 3 | M6: 8 | N6: 9 | O6: 8 | P6: 6 | Q6: 7 | R6: 7 | S6: 0 | T6: 2 | U6: 5 | V6: 7 | W6: 0 | X6: 5 | Y6: 9 | Z6: 7 | AA6: 0 | AB6: 3 | AC6: 6 | AD6: =SUM(E6:AC6)
A7: 6 | B7: Hatoon Saif Mansour Ibrahim | C7: هتون سيف منصور إبراهيم | D7: 516986974 | E7: 8 | F7: 0 | G7: 9 | H7: 9 | I7: 0 | J7: 7 | K7: 7 | L7: 2 | M7: 10 | N7: 2 | O7: 2 | P7: 9 | Q7: 10 | R7: 8 | S7: 6 | T7: 10 | U7: 3 | V7: 10 | W7: 6 | X7: 8 | Y7: 2 | Z7: 4 | AA7: 2 | AB7: 8 | AC7: 5 | AD7: =SUM(E7:AC7)
A8: 7 | B8: Wafa Abdullah Iyad Bassam | C8: وفاء عبدالله إياد بسام | D8: 554169921 | E8: 8 | F8: 5 | G8: 2 | H8: 6 | I8: 5 | J8: 4 | K8: 3 | L8: 4 | M8: 8 | N8: 9 | O8: 5 | P8: 6 | Q8: 8 | R8: 5 | S8: 1 | T8: 1 | U8: 7 | V8: 3 | W8: 7 | X8: 2 | Y8: 5 | Z8: 8 | AA8: 10 | AB8: 5 | AC8: 1 | AD8: =SUM(E8:AC8)
A9: 8 | B9: Amani Saad Nayef Hamad | C9: أماني سعد نايف حمد | D9: 591352868 | E9: 0 | F9: 1 | G9: 2 | H9: 5 | I9: 6 | J9: 9 | K9: 0 | L9: 9 | M9: 2 | N9: 0 | O9: 7 | P9: 3 | Q9: 2 | R9: 7 | S9: 10 | T9: 2 | U9: 2 | V9: 5 | W9: 10 | X9: 6 | Y9: 7 | Z9: 6 | AA9: 9 | AB9: 5 | AC9: 3 | AD9: =SUM(E9:AC9)
A10: 9 | B10: Moudi Hamed Hamad Tamim | C10: موضي حامد حمد تميم | D10: 628535815 | E10: 1 | F10: 9 | G10: 9 | H10: 8 | I10: 4 | J10: 3 | K10: 7 | L10: 3 | M10: 2 | N10: 6 | O10: 10 | P10: 2 | Q10: 5 | R10: 3 | S10: 2 | T10: 5 | U10: 3 | V10: 2 | W10: 7 | X10: 7 | Y10: 5 | Z10: 5 | AA10: 4 | AB10: 6 | AC10: 3 | AD10: =SUM(E10:AC10)
A11: 10 | B11: Layan Ziyad Adnan Omar | C11: ليان زياد عدنان عمر | D11: 665718762 | E11: 7 | F11: 3 | G11: 9 | H11: 0 | I11: 2 | J11: 7 | K11: 4 | L11: 2 | M11: 0 | N11: 6 | O11: 6 | P11: 1 | Q11: 1 | R11: 5 | S11: 2 | T11: 5 | U11: 9 | V11: 9 | W11: 0 | X11: 0 | Y11: 7 | Z11: 8 | AA11: 5 | AB11: 9 | AC11: 3 | AD11: =SUM(E11:AC11)
A12: 11 | B12: Rawan Rayan Rakan Fawaz | C12: روان ريان راكان فواز | D12: 702901709 | E12: 6 | F12: 8 | G12: 5 | H12: 5 | I12: 5 | J12: 2 | K12: 6 | L12: 5 | M12: 2 | N12: 6 | O12: 0 | P12: 5 | Q12: 9 | R12: 8 | S12: 7 | T12: 2 | U12: 10 | V12: 5 | W12: 5 | X12: 1 | Y12: 3 | Z12: 4 | AA12: 7 | AB12: 5 | AC12: 6 | AD12: =SUM(E12:AC12)
A13: 12 | B13: Sarah Faisal Mohannad Yousef | C13: سارة فيصل مهند يوسف | D13: 740084656 | E13: 0 | F13: 9 | G13: 4 | H13: 7 | I13: 4 | J13: 10 | K13: 6 | L13: 3 | M13: 10 | N13: 5 | O13: 1 | P13: 6 | Q13: 5 | R13: 1 | S13: 3 | T13: 10 | U13: 10 | V13: 5 | W13: 7 | X13: 5 | Y13: 1 | Z13: 7 | AA13: 8 | AB13: 3 | AC13: 2 | AD13: =SUM(E13:AC13)
... A36: 35 | B36: Leen Adnan Mohammed Waleed | C36: لين عدنان محمد وليد | D36: 595292437 | E36: 6 | F36: 4 | G36: 9 | H36: 1 | I36: 7 | J36: 7 | K36: 4 | L36: 3 | M36: 2 | N36: 2 | O36: 10 | P36: 4 | Q36: 8 | R36: 7 | S36: 1 | T36: 2 | U36: 10 | V36: 6 | W36: 10 | X36: 0 | Y36: 10 | Z36: 7 | AA36: 1 | AB36: 7 | AC36: 9 | AD36: =SUM(E36:AC36)
A37: 36 | B37: Noura Rayan Abdulaziz Rakan | C37: نورة ريان عبدالعزيز راكان | D37: 632475384 | E37: 3 | F37: 2 | G37: 10 | H37: 5 | I37: 1 | J37: 4 | K37: 10 | L37: 5 | M37: 0 | N37: 4 | O37: 7 | P37: 3 | Q37: 8 | R37: 8 | S37: 5 | T37: 5 | U37: 7 | V37: 8 | W37: 2 | X37: 2 | Y37: 3 | Z37: 4 | AA37: 10 | AB37: 5 | AC37: 9 | AD37: 9

Sheet Participation 11 FEMALES
A1: SN | B1: Name (English) | C1: Name (Arabic) | D1: Academic ID | E1: Day-1 | F1: Day-2 | G1: Day-3 | H1: Day-4 | I1: Day-5 | J1: Day-6 | K1: Day-7 | L1: Day-8 | M1: Day-9 | N1: Day-10 | O1: Day-11 | P1: Day-12 | Q1: Day-13 | R1: Day-14 | S1: Day-15 | T1: Day-16 | U1: Day-17 | V1: Day-18 | W1: Day-19 | X1: Day-20 | Y1: Day-21 | Z1: Day-22 | AA1: Day-23 | AB1: Day-24 | AC1: Day-25 | AD1: Total
A2: 1 | B2: Reema Rayan Nawaf Abdullah | C2: ريما ريان نواف عبدالله | D2: 333072239 | E2: 8 | F2: 5 | G2: 10 | H2: 3 | I2: 2 | J2: 10 | K2: 3 | L2: 4 | M2: 6 | N2: 10 | O2: 7 | P2: 2 | Q2: 4 | R2: 5 | S2: 10 | T2: 10 | U2: 0 | V2: 5 | W2: 5 | X2: 3 | Y2: 2 | Z2: 3 | AA2: 10 | AB2: 5 | AC2: 1 | AD2: =SUM(F2:P2)
A3: 2 | B3: Reema Jaber Abdullah Mazen | C3: ريما جابر عبدالله مازن | D3: 370255186 | E3: 3 | F3: 5 | G3: 6 | H3: 4 | I3: 7 | J3: 4 | K3: 8 | L3: 3 | M3: 7 | N3: 7 | O3: 9 | P3: 2 | Q3: 6 | R3: 4 | S3: 10 | T3: 0 | U3: 4 | V3: 8 | W3: 7 | X3: 3 | Y3: 6 | Z3: 7 | AA3: 6 | AB3: 4 | AC3: 5 | AD3: =SUM(F3:P3)
A4: 3 | B4: Ghada Nayef Yazeed Marwan | C4: غادة نايف يزيد مروان | D4: 407438133 | E4: 9 | F4: 5 | G4: 8 | H4: 9 | I4: 4 | J4: 6 | K4: 3 | L4: 9 | M4: 3 | N4: 2 | O4: 7 | P4: 7 | Q4: 1 | R4: 9 | S4: 0 | T4: 2 | U4: 8 | V4: 2 | W4: 9 | X4: 5 | Y4: 10 | Z4: 0 | AA4: 3 | AB4: 4 | AC4: 4 | AD4: =SUM(F4:P4)
A5: 4 | B5: Raghad Faisal Anas Yousef | C5: رغد فيصل أنس يوسف | D5: 444621080 | E5: 10 | F5: 7 | G5: 4 | H5: 3 | I5: 5 | J5: 4 | K5: 1 | L5: 6 | M5: 5 | N5: 3 | O5: 6 | P5: 7 | Q5: 6 | R5: 4 | S5: 8 | T5: 5 | U5: 0 | V5: 6 | W5: 8 | X5: 0 | Y5: 9 | Z5: 10 | AA5: 1 | AB5: 10 | AC5: 7 | AD5: =SUM(F5:P5)
A6: 5 | B6: Atheer Hussam Majed Ali | C6: أثير حسام ماجد علي | D6: 481804027 | E6: 4 | F6: 6 | G6: 3 | H6: 4 | I6: 7 | J6: 1 | K6: 0 | L6: 5 | M6: 2 | N6: 1 | O6: 7 | P6: 4 | Q6: 0 | R6: 1 | S6: 8 | T6: 8 | U6: 6 | V6: 5 | W6: 4 | X6: 7 | Y6: 4 | Z6: 3 | AA6: 1 | AB6: 3 | AC6: 9 | AD6: =SUM(F6:P6)
A7: 6 | B7: Wadha Hussein Mazen Abdulmalik | C7: وضحى حسين مازن عبدالملك | D7: 518986974 | E7: 9 | F7: 2 | G7: 5 | H7: 10 | I7: 0 | J7: 6 | K7: 4 | L7: 0 | M7: 4 | N7: 6 | O7: 2 | P7: 2 | Q7: 9 | R7: 6 | S7: 9 | T7: 8 | U7: 3 | V7: 5 | W7: 1 | X7: 1 | Y7: 1 | Z7: 4 | AA7: 4 | AB7: 8 | AC7: 0 | AD7: =SUM(F7:P7)
A8: 7 | B8: Jana Abdullah Badr Ziyad | C8: جنى عبدالله بدر زياد | D8: 556169921 | E8: 8 | F8: 5 | G8: 9 | H8: 1 | I8: 0 | J8: 2 | K8: 7 | L8: 7 | M8: 4 | N8: 8 | O8: 10 | P8: 2 | Q8: 8 | R8: 4 | S8: 5 | T8: 3 | U8: 4 | V8: 1 | W8: 9 | X8: 5 | Y8: 4 | Z8: 0 | AA8: 3 | AB8: 8 | AC8: 7 | AD8: =SUM(F8:P8)
A9: 8 | B9: Afnan Saleh Abdulrahman Badr | C9: أفنان صالح عبدالرحمن بدر | D9: 593352868 | E9: 8 | F9: 9 | G9: 1 | H9: 5 | I9: 10 | J9: 7 | K9: 5 | L9: 7 | M9: 8 | N9: 7 | O9: 1 | P9: 3 | Q9: 7 | R9: 2 | S9: 5 | T9: 5 | U9: 8 | V9: 7 | W9: 7 | X9: 5 | Y9: 8 | Z9: 0 | AA9: 8 | AB9: 6 | AC9: 1 | AD9: =SUM(F9:P9)
A10: 9 | B10: Haneen Marwan Mansour Hadi | C10: حنين مروان منصور هادي | D10: 630535815 | E10: 3 | F10: 7 | G10: 10 | H10: 1 | I10: 3 | J10: 7 | K10: 6 | L10: 9 | M10: 5 | N10: 3 | O10: 7 | P10: 6 | Q10: 4 | R10: 8 | S10: 4 | T10: 3 | U10: 4 | V10: 2 | W10: 10 | X10: 10 | Y10: 3 | Z10: 1 | AA10: 4 | AB10: 3 | AC10: 3 | AD10: =SUM(F10:P10)
A11: 10 | B11: Fatimah Saleh Saud Ali | C11: فاطمة صالح سعود علي | D11: 667718762 | E11: 2 | F11: 3 | G11: 6 | H11: 2 | I11: 5 | J11: 3 | K11: 2 | L11: 10 | M11: 0 | N11: 6 | O11: 7 | P11: 2 | Q11: 7 | R11: 3 | S11: 10 | T11: 4 | U11: 4 | V11: 2 | W11: 2 | X11: 0 | Y11: 10 | Z11: 9 | AA11: 7 | AB11: 7 | AC11: 2 | AD11: =SUM(F11:P11)
A12: 11 | B12: Fatimah Basheer Nayef Faris | C12: فاطمة بشير نايف فارس | D12: 704901709 | E12: 5 | F12: 5 | G12: 8 | H12: 9 | I12: 7 | J12: 1 | K12: 9 | L12: 10 | M12: 2 | N12: 3 | O12: 7 | P12: 4 | Q12: 1 | R12: 3 | S12: 7 | T12: 7 | U12: 2 | V12: 6 | W12: 2 | X12: 7 | Y12: 0 | Z12: 3 | AA12: 2 | AB12: 10 | AC12: 1 | AD12: =SUM(F12:P12)
A13: 12 | B13: Mashael Rami Marwan Basheer | C13: مشاعل رامي مروان بشير | D13: 742084656 | E13: 3 | F13: 7 | G13: 2 | H13: 7 | I13: 3 | J13: 4 | K13: 9 | L13: 10 | M13: 2 | N13: 4 | O13: 1 | P13: 2 | Q13: 9 | R13: 3 | S13: 6 | T13: 10 | U13: 10 | V13: 0 | W13: 0 | X13: 3 | Y13: 6 | Z13: 4 | AA13: 0 | AB13: 6 | AC13: 1 | AD13: =SUM(F13:P13)
... A40: 39 | B40: Haya Saleh Rakan Rayan | C40: هيا صالح راكان ريان | D40: 746024225 | E40: 7 | F40: 2 | G40: 0 | H40: 6 | I40: 7 | J40: 0 | K40: 10 | L40: 3 | M40: 9 | N40: 10 | O40: 0 | P40: 10 | Q40: 4 | R40: 8 | S40: 0 | T40: 10 | U40: 4 | V40: 8 | W40: 7 | X40: 5 | Y40: 8 | Z40: 8 | AA40: 10 | AB40: 6 | AC40: 3 | AD40: =SUM(F40:P40)
E41: 7 | F41: 5 | G41: 4 | H41: 8 | I41: 10 | J41: 10 | K41: 8 | L41: 6 | M41: 9 | N41: 5 | O41: 10 | P41: 2 | Q41: 10 | R41: 9 | S41: 8 | T41: 0 | U41: 10 | V41: 10 | W41: 1 | X41: 5 | Y41: 7 | Z41: 3 | AA41: 7 | AB41: 6 | AC41: 9 | AD41: 10
E42: 10 | F42: 2 | G42: 8 | H42: 10 | I42: 0 | J42: 4 | K42: 0 | L42: 3 | M42: 2 | N42: 6 | O42: 3 | P42: 7 | Q42: 6 | R42: 6 | S42: 1 | T42: 8 | U42: 2 | V42: 6 | W42: 4 | X42: 2 | Y42: 0 | Z42: 8 | AA42: 10 | AB42: 2 | AC42: 7 | AD42: 8

